Workbook

Sheet Settings
B1: Settings and reference durations
B2: Blue text on cream is an input. Everything else is a formula.
J3: Days off (holidays, leave) | K3: One date per cell. Skipped by all date formulas.
B4: Working hours per day (Lara) | C4: 6 | D4: Her average, from Lara.
B5: Working days per week | C5: 5 | D5: Monday to Friday, confirmed.
B6: Reference apartment area (m2) | C6: 50 | D6: Size the reference weeks apply to.
B7: Idle working days between phases | C7: 0 | D7: Extra waiting time between any two phases. 0 = back to back.
B8: Gantt first week (Monday) | C8: =MIN(Schedule!$G$5:$G$34)-WEEKDAY(MIN(Schedule!$G$5:$G$34),2)+1 | D8: Monday of the earliest project start. Overwrite with a date to pin the timeline.
B11: Phase | C11: Owner | D11: Reference weeks | E11: Scaling exponent | F11: Ref. working days | G11: Ref. hours | H11: Why this scaling
B12: Brief and concept | C12: Anahit | D12: 1 | E12: 0 | F12: =D12*$C$5 | G12: =IF(C12="Lara",F12*$C$4,0) | H12: Fixed. A conversation and a mood board take the same time at any size. Placeholder.
B13: Floor planning | C13: Lara | D13: 1 | E13: 0.5 | F13: =D13*$C$5 | G13: =IF(C13="Lara",F13*$C$4,0) | H13: Layout effort follows room count and circulation problems, not area. Weak scaling.
B14: 3D modeling | C14: Lara | D14: 2 | E14: 0.9 | F14: =D14*$C$5 | G14: =IF(C14="Lara",F14*$C$4,0) | H14: Every surface gets modeled and materials assigned, so it tracks area closely.
B15: Client approval | C15: Anahit | D15: 1 | E15: 0 | F15: =D15*$C$5 | G15: =IF(C15="Lara",F15*$C$4,0) | H15: Waiting on the client. Fixed. Placeholder.
B16: Technical drawings | C16: Lara | D16: 1 | E16: 0.8 | F16: =D16*$C$5 | G16: =IF(C16="Lara",F16*$C$4,0) | H16: Sheet count follows rooms and wall and ceiling detail. Mostly area driven.
B17: Furniture drawings | C17: Lara | D17: 2 | E17: 0.7 | F17: =D17*$C$5 | G17: =IF(C17="Lara",F17*$C$4,0) | H17: Driven by the number of custom pieces, which grows slower than area.
B18: Procurement | C18: Anahit | D18: 3 | E18: 0 | F18: =D18*$C$5 | G18: =IF(C18="Lara",F18*$C$4,0) | H18: Ordering and lead times, mostly fixed. Placeholder.
B19: Site supervision | C19: Anahit | D19: 6 | E19: 0.5 | F19: =D19*$C$5 | G19: =IF(C19="Lara",F19*$C$4,0) | H19: Longer for bigger sites but not in proportion. Placeholder.
B20: Total | D20: =SUM(D12:D19) | F20: =SUM(F12:F19) | G20: =SUM(G12:G19)
B21: Ref. hours counts Lara's phases only. Lara's four phases total 6 weeks, 30 days, 180 hours at 50 m2.
B23: How duration is calculated
B24: Working days = ref. weeks x days per week x (area / ref. area) ^ exponent, then x complexity / share of Lara's time (Lara phases only).
B25: Exponent 1.0 would be strictly linear. Below 1.0, a larger apartment takes less time per m2. 0 means fixed regardless of size.
B26: The exponents are my design judgement, not measured data. Compare against 3 or 4 finished projects and adjust.
B27: Complexity (Schedule sheet) is a per project multiplier: 1.0 normal, above 1.0 for heavy joinery or tricky layouts.
B28: Share of Lara's time: 100% means the reference pace. Two parallel projects at 50% each run at half pace, so each takes twice as long.

Sheet Schedule
A1: Designature Studio project schedule
A2: Fill the blue columns B to H and Notes. Each project has its own start date, so projects run in parallel. The Lara load row at the bottom shows when she is overbooked. Examples 01 to 06 are invented placeholders.
I3: =Settings!$C$12 | L3: =Settings!$C$13 | O3: =Settings!$C$14 | R3: =Settings!$C$15 | U3: =Settings!$C$16 | X3: =Settings!$C$17 | AA3: =Settings!$C$18 | AD3: =Settings!$C$19 | AK3: Weekly timeline, one column per week starting Monday
A4: # | B4: Project | C4: Client | D4: Area (m2) | E4: Complexity | F4: Share of Lara's time | G4: Start | H4: Status | I4: Brief and concept days | J4: start | K4: end | L4: Floor planning days | M4: start | N4: end | O4: 3D modeling days | P4: start | Q4: end | R4: Client approval days | S4: start | T4: end | U4: Technical drawings days | V4: start | W4: end | X4: Furniture drawings days | Y4: start | Z4: end | AA4: Procurement days | AB4: start | AC4: end | AD4: Site supervision days | AE4: start | AF4: end | AG4: Finish | AH4: Lara hours | AI4: Notes | AK4: =Settings!$C$8 | AL4: =AK4+7 | AM4: =AL4+7 | AN4: =AM4+7 | AO4: =AN4+7 | AP4: =AO4+7 | AQ4: =AP4+7 | AR4: =AQ4+7 | AS4: =AR4+7 | ... CR4: =CQ4+7
A5: 1 | B5: Example 01 | C5: Client A | D5: 50 | E5: 1 | F5: 1 | G5: 46300 | H5: Active | I5: =IF($D5="",0,IF(Settings!$D$12=0,0,MAX(1,ROUND(Settings!$D$12*Settings!$C$5*($D5/Settings!$C$6)^Settings!$E$12*IF(Settings!$C$12="Lara",$E5/$F5,1),0)))) | J5: =IF($G5="",0,WORKDAY($G5-1,1,Settings!$J$4:$J$23)) | K5: =IF(J5=0,0,IF(I5=0,J5,WORKDAY(J5,I5-1,Settings!$J$4:$J$23))) | L5: =IF($D5="",0,IF(Settings!$D$13=0,0,MAX(1,ROUND(Settings!$D$13*Settings!$C$5*($D5/Settings!$C$6)^Settings!$E$13*IF(Settings!$C$13="Lara",$E5/$F5,1),0)))) | M5: =IF(K5=0,0,IF(L5=0,K5,WORKDAY(K5,1+Settings!$C$7,Settings!$J$4:$J$23))) | N5: =IF(M5=0,0,IF(L5=0,M5,WORKDAY(M5,L5-1,Settings!$J$4:$J$23))) | O5: =IF($D5="",0,IF(Settings!$D$14=0,0,MAX(1,ROUND(Settings!$D$14*Settings!$C$5*($D5/Settings!$C$6)^Settings!$E$14*IF(Settings!$C$14="Lara",$E5/$F5,1),0)))) | P5: =IF(N5=0,0,IF(O5=0,N5,WORKDAY(N5,1+Settings!$C$7,Settings!$J$4:$J$23))) | Q5: =IF(P5=0,0,IF(O5=0,P5,WORKDAY(P5,O5-1,Settings!$J$4:$J$23))) | R5: =IF($D5="",0,IF(Settings!$D$15=0,0,MAX(1,ROUND(Settings!$D$15*Settings!$C$5*($D5/Settings!$C$6)^Settings!$E$15*IF(Settings!$C$15="Lara",$E5/$F5,1),0)))) | S5: =IF(Q5=0,0,IF(R5=0,Q5,WORKDAY(Q5,1+Settings!$C$7,Settings!$J$4:$J$23))) | T5: =IF(S5=0,0,IF(R5=0,S5,WORKDAY(S5,R5-1,Settings!$J$4:$J$23))) | U5: =IF($D5="",0,IF(Settings!$D$16=0,0,MAX(1,ROUND(Settings!$D$16*Settings!$C$5*($D5/Settings!$C$6)^Settings!$E$16*IF(Settings!$C$16="Lara",$E5/$F5,1),0)))) | V5: =IF(T5=0,0,IF(U5=0,T5,WORKDAY(T5,1+Settings!$C$7,Settings!$J$4:$J$23))) | W5: =IF(V5=0,0,IF(U5=0,V5,WORKDAY(V5,U5-1,Settings!$J$4:$J$23))) | X5: =IF($D5="",0,IF(Settings!$D$17=0,0,MAX(1,ROUND(Settings!$D$17*Settings!$C$5*($D5/Settings!$C$6)^Settings!$E$17*IF(Settings!$C$17="Lara",$E5/$F5,1),0)))) | Y5: =IF(W5=0,0,IF(X5=0,W5,WORKDAY(W5,1+Settings!$C$7,Settings!$J$4:$J$23))) | Z5: =IF(Y5=0,0,IF(X5=0,Y5,WORKDAY(Y5,X5-1,Settings!$J$4:$J$23))) | AA5: =IF($D5="",0,IF(Settings!$D$18=0,0,MAX(1,ROUND(Settings!$D$18*Settings!$C$5*($D5/Settings!$C$6)^Settings!$E$18*IF(Settings!$C$18="Lara",$E5/$F5,1),0)))) | AB5: =IF(Z5=0,0,IF(AA5=0,Z5,WORKDAY(Z5,1+Settings!$C$7,Settings!$J$4:$J$23))) | AC5: =IF(AB5=0,0,IF(AA5=0,AB5,WORKDAY(AB5,AA5-1,Settings!$J$4:$J$23))) | AD5: =IF($D5="",0,IF(Settings!$D$19=0,0,MAX(1,ROUND(Settings!$D$19*Settings!$C$5*($D5/Settings!$C$6)^Settings!$E$19*IF(Settings!$C$19="Lara",$E5/$F5,1),0)))) | AE5: =IF(AC5=0,0,IF(AD5=0,AC5,WORKDAY(AC5,1+Settings!$C$7,Settings!$J$4:$J$23))) | AF5: =IF(AE5=0,0,IF(AD5=0,AE5,WORKDAY(AE5,AD5-1,Settings!$J$4:$J$23))) | AG5: =AF5 | AH5: =IF($D5="",0,(I5*(Settings!$C$12="Lara")+L5*(Settings!$C$13="Lara")+O5*(Settings!$C$14="Lara")+R5*(Settings!$C$15="Lara")+U5*(Settings!$C$16="Lara")+X5*(Settings!$C$17="Lara")+AA5*(Settings!$C$18="Lara")+AD5*(Settings!$C$19="Lara"))*$F5*Settings!$C$4) | AI5: Reference size, Lara full time
A6: 2 | B6: Example 02 | C6: Client B | D6: 72 | E6: 1 | F6: 0.5 | G6: 46314 | H6: Planned | I6: =IF($D6="",0,IF(Settings!$D$12=0,0,MAX(1,ROUND(Settings!$D$12*Settings!$C$5*($D6/Settings!$C$6)^Settings!$E$12*IF(Settings!$C$12="Lara",$E6/$F6,1),0)))) | J6: =IF($G6="",0,WORKDAY($G6-1,1,Settings!$J$4:$J$23)) | K6: =IF(J6=0,0,IF(I6=0,J6,WORKDAY(J6,I6-1,Settings!$J$4:$J$23))) | L6: =IF($D6="",0,IF(Settings!$D$13=0,0,MAX(1,ROUND(Settings!$D$13*Settings!$C$5*($D6/Settings!$C$6)^Settings!$E$13*IF(Settings!$C$13="Lara",$E6/$F6,1),0)))) | M6: =IF(K6=0,0,IF(L6=0,K6,WORKDAY(K6,1+Settings!$C$7,Settings!$J$4:$J$23))) | N6: =IF(M6=0,0,IF(L6=0,M6,WORKDAY(M6,L6-1,Settings!$J$4:$J$23))) | O6: =IF($D6="",0,IF(Settings!$D$14=0,0,MAX(1,ROUND(Settings!$D$14*Settings!$C$5*($D6/Settings!$C$6)^Settings!$E$14*IF(Settings!$C$14="Lara",$E6/$F6,1),0)))) | P6: =IF(N6=0,0,IF(O6=0,N6,WORKDAY(N6,1+Settings!$C$7,Settings!$J$4:$J$23))) | Q6: =IF(P6=0,0,IF(O6=0,P6,WORKDAY(P6,O6-1,Settings!$J$4:$J$23))) | R6: =IF($D6="",0,IF(Settings!$D$15=0,0,MAX(1,ROUND(Settings!$D$15*Settings!$C$5*($D6/Settings!$C$6)^Settings!$E$15*IF(Settings!$C$15="Lara",$E6/$F6,1),0)))) | S6: =IF(Q6=0,0,IF(R6=0,Q6,WORKDAY(Q6,1+Settings!$C$7,Settings!$J$4:$J$23))) | T6: =IF(S6=0,0,IF(R6=0,S6,WORKDAY(S6,R6-1,Settings!$J$4:$J$23))) | U6: =IF($D6="",0,IF(Settings!$D$16=0,0,MAX(1,ROUND(Settings!$D$16*Settings!$C$5*($D6/Settings!$C$6)^Settings!$E$16*IF(Settings!$C$16="Lara",$E6/$F6,1),0)))) | V6: =IF(T6=0,0,IF(U6=0,T6,WORKDAY(T6,1+Settings!$C$7,Settings!$J$4:$J$23))) | W6: =IF(V6=0,0,IF(U6=0,V6,WORKDAY(V6,U6-1,Settings!$J$4:$J$23))) | X6: =IF($D6="",0,IF(Settings!$D$17=0,0,MAX(1,ROUND(Settings!$D$17*Settings!$C$5*($D6/Settings!$C$6)^Settings!$E$17*IF(Settings!$C$17="Lara",$E6/$F6,1),0)))) | Y6: =IF(W6=0,0,IF(X6=0,W6,WORKDAY(W6,1+Settings!$C$7,Settings!$J$4:$J$23))) | Z6: =IF(Y6=0,0,IF(X6=0,Y6,WORKDAY(Y6,X6-1,Settings!$J$4:$J$23))) | AA6: =IF($D6="",0,IF(Settings!$D$18=0,0,MAX(1,ROUND(Settings!$D$18*Settings!$C$5*($D6/Settings!$C$6)^Settings!$E$18*IF(Settings!$C$18="Lara",$E6/$F6,1),0)))) | AB6: =IF(Z6=0,0,IF(AA6=0,Z6,WORKDAY(Z6,1+Settings!$C$7,Settings!$J$4:$J$23))) | AC6: =IF(AB6=0,0,IF(AA6=0,AB6,WORKDAY(AB6,AA6-1,Settings!$J$4:$J$23))) | AD6: =IF($D6="",0,IF(Settings!$D$19=0,0,MAX(1,ROUND(Settings!$D$19*Settings!$C$5*($D6/Settings!$C$6)^Settings!$E$19*IF(Settings!$C$19="Lara",$E6/$F6,1),0)))) | AE6: =IF(AC6=0,0,IF(AD6=0,AC6,WORKDAY(AC6,1+Settings!$C$7,Settings!$J$4:$J$23))) | AF6: =IF(AE6=0,0,IF(AD6=0,AE6,WORKDAY(AE6,AD6-1,Settings!$J$4:$J$23))) | AG6: =AF6 | AH6: =IF($D6="",0,(I6*(Settings!$C$12="Lara")+L6*(Settings!$C$13="Lara")+O6*(Settings!$C$14="Lara")+R6*(Settings!$C$15="Lara")+U6*(Settings!$C$16="Lara")+X6*(Settings!$C$17="Lara")+AA6*(Settings!$C$18="Lara")+AD6*(Settings!$C$19="Lara"))*$F6*Settings!$C$4) | AI6: Parallel with 01 and 03, half her time
A7: 3 | B7: Example 03 | C7: Client C | D7: 38 | E7: 0.9 | F7: 0.5 | G7: 46321 | H7: Planned | I7: =IF($D7="",0,IF(Settings!$D$12=0,0,MAX(1,ROUND(Settings!$D$12*Settings!$C$5*($D7/Settings!$C$6)^Settings!$E$12*IF(Settings!$C$12="Lara",$E7/$F7,1),0)))) | J7: =IF($G7="",0,WORKDAY($G7-1,1,Settings!$J$4:$J$23)) | K7: =IF(J7=0,0,IF(I7=0,J7,WORKDAY(J7,I7-1,Settings!$J$4:$J$23))) | L7: =IF($D7="",0,IF(Settings!$D$13=0,0,MAX(1,ROUND(Settings!$D$13*Settings!$C$5*($D7/Settings!$C$6)^Settings!$E$13*IF(Settings!$C$13="Lara",$E7/$F7,1),0)))) | M7: =IF(K7=0,0,IF(L7=0,K7,WORKDAY(K7,1+Settings!$C$7,Settings!$J$4:$J$23))) | N7: =IF(M7=0,0,IF(L7=0,M7,WORKDAY(M7,L7-1,Settings!$J$4:$J$23))) | O7: =IF($D7="",0,IF(Settings!$D$14=0,0,MAX(1,ROUND(Settings!$D$14*Settings!$C$5*($D7/Settings!$C$6)^Settings!$E$14*IF(Settings!$C$14="Lara",$E7/$F7,1),0)))) | P7: =IF(N7=0,0,IF(O7=0,N7,WORKDAY(N7,1+Settings!$C$7,Settings!$J$4:$J$23))) | Q7: =IF(P7=0,0,IF(O7=0,P7,WORKDAY(P7,O7-1,Settings!$J$4:$J$23))) | R7: =IF($D7="",0,IF(Settings!$D$15=0,0,MAX(1,ROUND(Settings!$D$15*Settings!$C$5*($D7/Settings!$C$6)^Settings!$E$15*IF(Settings!$C$15="Lara",$E7/$F7,1),0)))) | S7: =IF(Q7=0,0,IF(R7=0,Q7,WORKDAY(Q7,1+Settings!$C$7,Settings!$J$4:$J$23))) | T7: =IF(S7=0,0,IF(R7=0,S7,WORKDAY(S7,R7-1,Settings!$J$4:$J$23))) | U7: =IF($D7="",0,IF(Settings!$D$16=0,0,MAX(1,ROUND(Settings!$D$16*Settings!$C$5*($D7/Settings!$C$6)^Settings!$E$16*IF(Settings!$C$16="Lara",$E7/$F7,1),0)))) | V7: =IF(T7=0,0,IF(U7=0,T7,WORKDAY(T7,1+Settings!$C$7,Settings!$J$4:$J$23))) | W7: =IF(V7=0,0,IF(U7=0,V7,WORKDAY(V7,U7-1,Settings!$J$4:$J$23))) | X7: =IF($D7="",0,IF(Settings!$D$17=0,0,MAX(1,ROUND(Settings!$D$17*Settings!$C$5*($D7/Settings!$C$6)^Settings!$E$17*IF(Settings!$C$17="Lara",$E7/$F7,1),0)))) | Y7: =IF(W7=0,0,IF(X7=0,W7,WORKDAY(W7,1+Settings!$C$7,Settings!$J$4:$J$23))) | Z7: =IF(Y7=0,0,IF(X7=0,Y7,WORKDAY(Y7,X7-1,Settings!$J$4:$J$23))) | AA7: =IF($D7="",0,IF(Settings!$D$18=0,0,MAX(1,ROUND(Settings!$D$18*Settings!$C$5*($D7/Settings!$C$6)^Settings!$E$18*IF(Settings!$C$18="Lara",$E7/$F7,1),0)))) | AB7: =IF(Z7=0,0,IF(AA7=0,Z7,WORKDAY(Z7,1+Settings!$C$7,Settings!$J$4:$J$23))) | AC7: =IF(AB7=0,0,IF(AA7=0,AB7,WORKDAY(AB7,AA7-1,Settings!$J$4:$J$23))) | AD7: =IF($D7="",0,IF(Settings!$D$19=0,0,MAX(1,ROUND(Settings!$D$19*Settings!$C$5*($D7/Settings!$C$6)^Settings!$E$19*IF(Settings!$C$19="Lara",$E7/$F7,1),0)))) | AE7: =IF(AC7=0,0,IF(AD7=0,AC7,WORKDAY(AC7,1+Settings!$C$7,Settings!$J$4:$J$23))) | AF7: =IF(AE7=0,0,IF(AD7=0,AE7,WORKDAY(AE7,AD7-1,Settings!$J$4:$J$23))) | AG7: =AF7 | AH7: =IF($D7="",0,(I7*(Settings!$C$12="Lara")+L7*(Settings!$C$13="Lara")+O7*(Settings!$C$14="Lara")+R7*(Settings!$C$15="Lara")+U7*(Settings!$C$16="Lara")+X7*(Settings!$C$17="Lara")+AA7*(Settings!$C$18="Lara")+AD7*(Settings!$C$19="Lara"))*$F7*Settings!$C$4) | AI7: Small, simple layout
A8: 4 | B8: Example 04 | C8: Client D | D8: 95 | E8: 1.2 | F8: 1 | G8: 46342 | H8: Planned | I8: =IF($D8="",0,IF(Settings!$D$12=0,0,MAX(1,ROUND(Settings!$D$12*Settings!$C$5*($D8/Settings!$C$6)^Settings!$E$12*IF(Settings!$C$12="Lara",$E8/$F8,1),0)))) | J8: =IF($G8="",0,WORKDAY($G8-1,1,Settings!$J$4:$J$23)) | K8: =IF(J8=0,0,IF(I8=0,J8,WORKDAY(J8,I8-1,Settings!$J$4:$J$23))) | L8: =IF($D8="",0,IF(Settings!$D$13=0,0,MAX(1,ROUND(Settings!$D$13*Settings!$C$5*($D8/Settings!$C$6)^Settings!$E$13*IF(Settings!$C$13="Lara",$E8/$F8,1),0)))) | M8: =IF(K8=0,0,IF(L8=0,K8,WORKDAY(K8,1+Settings!$C$7,Settings!$J$4:$J$23))) | N8: =IF(M8=0,0,IF(L8=0,M8,WORKDAY(M8,L8-1,Settings!$J$4:$J$23))) | O8: =IF($D8="",0,IF(Settings!$D$14=0,0,MAX(1,ROUND(Settings!$D$14*Settings!$C$5*($D8/Settings!$C$6)^Settings!$E$14*IF(Settings!$C$14="Lara",$E8/$F8,1),0)))) | P8: =IF(N8=0,0,IF(O8=0,N8,WORKDAY(N8,1+Settings!$C$7,Settings!$J$4:$J$23))) | Q8: =IF(P8=0,0,IF(O8=0,P8,WORKDAY(P8,O8-1,Settings!$J$4:$J$23))) | R8: =IF($D8="",0,IF(Settings!$D$15=0,0,MAX(1,ROUND(Settings!$D$15*Settings!$C$5*($D8/Settings!$C$6)^Settings!$E$15*IF(Settings!$C$15="Lara",$E8/$F8,1),0)))) | S8: =IF(Q8=0,0,IF(R8=0,Q8,WORKDAY(Q8,1+Settings!$C$7,Settings!$J$4:$J$23))) | T8: =IF(S8=0,0,IF(R8=0,S8,WORKDAY(S8,R8-1,Settings!$J$4:$J$23))) | U8: =IF($D8="",0,IF(Settings!$D$16=0,0,MAX(1,ROUND(Settings!$D$16*Settings!$C$5*($D8/Settings!$C$6)^Settings!$E$16*IF(Settings!$C$16="Lara",$E8/$F8,1),0)))) | V8: =IF(T8=0,0,IF(U8=0,T8,WORKDAY(T8,1+Settings!$C$7,Settings!$J$4:$J$23))) | W8: =IF(V8=0,0,IF(U8=0,V8,WORKDAY(V8,U8-1,Settings!$J$4:$J$23))) | X8: =IF($D8="",0,IF(Settings!$D$17=0,0,MAX(1,ROUND(Settings!$D$17*Settings!$C$5*($D8/Settings!$C$6)^Settings!$E$17*IF(Settings!$C$17="Lara",$E8/$F8,1),0)))) | Y8: =IF(W8=0,0,IF(X8=0,W8,WORKDAY(W8,1+Settings!$C$7,Settings!$J$4:$J$23))) | Z8: =IF(Y8=0,0,IF(X8=0,Y8,WORKDAY(Y8,X8-1,Settings!$J$4:$J$23))) | AA8: =IF($D8="",0,IF(Settings!$D$18=0,0,MAX(1,ROUND(Settings!$D$18*Settings!$C$5*($D8/Settings!$C$6)^Settings!$E$18*IF(Settings!$C$18="Lara",$E8/$F8,1),0)))) | AB8: =IF(Z8=0,0,IF(AA8=0,Z8,WORKDAY(Z8,1+Settings!$C$7,Settings!$J$4:$J$23))) | AC8: =IF(AB8=0,0,IF(AA8=0,AB8,WORKDAY(AB8,AA8-1,Settings!$J$4:$J$23))) | AD8: =IF($D8="",0,IF(Settings!$D$19=0,0,MAX(1,ROUND(Settings!$D$19*Settings!$C$5*($D8/Settings!$C$6)^Settings!$E$19*IF(Settings!$C$19="Lara",$E8/$F8,1),0)))) | AE8: =IF(AC8=0,0,IF(AD8=0,AC8,WORKDAY(AC8,1+Settings!$C$7,Settings!$J$4:$J$23))) | AF8: =IF(AE8=0,0,IF(AD8=0,AE8,WORKDAY(AE8,AD8-1,Settings!$J$4:$J$23))) | AG8: =AF8 | AH8: =IF($D8="",0,(I8*(Settings!$C$12="Lara")+L8*(Settings!$C$13="Lara")+O8*(Settings!$C$14="Lara")+R8*(Settings!$C$15="Lara")+U8*(Settings!$C$16="Lara")+X8*(Settings!$C$17="Lara")+AA8*(Settings!$C$18="Lara")+AD8*(Settings!$C$19="Lara"))*$F8*Settings!$C$4) | AI8: Lots of custom joinery
A9: 5 | B9: Example 05 | C9: Client E | D9: 60 | E9: 1 | F9: 0.6 | G9: 46363 | H9: Planned | I9: =IF($D9="",0,IF(Settings!$D$12=0,0,MAX(1,ROUND(Settings!$D$12*Settings!$C$5*($D9/Settings!$C$6)^Settings!$E$12*IF(Settings!$C$12="Lara",$E9/$F9,1),0)))) | J9: =IF($G9="",0,WORKDAY($G9-1,1,Settings!$J$4:$J$23)) | K9: =IF(J9=0,0,IF(I9=0,J9,WORKDAY(J9,I9-1,Settings!$J$4:$J$23))) | L9: =IF($D9="",0,IF(Settings!$D$13=0,0,MAX(1,ROUND(Settings!$D$13*Settings!$C$5*($D9/Settings!$C$6)^Settings!$E$13*IF(Settings!$C$13="Lara",$E9/$F9,1),0)))) | M9: =IF(K9=0,0,IF(L9=0,K9,WORKDAY(K9,1+Settings!$C$7,Settings!$J$4:$J$23))) | N9: =IF(M9=0,0,IF(L9=0,M9,WORKDAY(M9,L9-1,Settings!$J$4:$J$23))) | O9: =IF($D9="",0,IF(Settings!$D$14=0,0,MAX(1,ROUND(Settings!$D$14*Settings!$C$5*($D9/Settings!$C$6)^Settings!$E$14*IF(Settings!$C$14="Lara",$E9/$F9,1),0)))) | P9: =IF(N9=0,0,IF(O9=0,N9,WORKDAY(N9,1+Settings!$C$7,Settings!$J$4:$J$23))) | Q9: =IF(P9=0,0,IF(O9=0,P9,WORKDAY(P9,O9-1,Settings!$J$4:$J$23))) | R9: =IF($D9="",0,IF(Settings!$D$15=0,0,MAX(1,ROUND(Settings!$D$15*Settings!$C$5*($D9/Settings!$C$6)^Settings!$E$15*IF(Settings!$C$15="Lara",$E9/$F9,1),0)))) | S9: =IF(Q9=0,0,IF(R9=0,Q9,WORKDAY(Q9,1+Settings!$C$7,Settings!$J$4:$J$23))) | T9: =IF(S9=0,0,IF(R9=0,S9,WORKDAY(S9,R9-1,Settings!$J$4:$J$23))) | U9: =IF($D9="",0,IF(Settings!$D$16=0,0,MAX(1,ROUND(Settings!$D$16*Settings!$C$5*($D9/Settings!$C$6)^Settings!$E$16*IF(Settings!$C$16="Lara",$E9/$F9,1),0)))) | V9: =IF(T9=0,0,IF(U9=0,T9,WORKDAY(T9,1+Settings!$C$7,Settings!$J$4:$J$23))) | W9: =IF(V9=0,0,IF(U9=0,V9,WORKDAY(V9,U9-1,Settings!$J$4:$J$23))) | X9: =IF($D9="",0,IF(Settings!$D$17=0,0,MAX(1,ROUND(Settings!$D$17*Settings!$C$5*($D9/Settings!$C$6)^Settings!$E$17*IF(Settings!$C$17="Lara",$E9/$F9,1),0)))) | Y9: =IF(W9=0,0,IF(X9=0,W9,WORKDAY(W9,1+Settings!$C$7,Settings!$J$4:$J$23))) | Z9: =IF(Y9=0,0,IF(X9=0,Y9,WORKDAY(Y9,X9-1,Settings!$J$4:$J$23))) | AA9: =IF($D9="",0,IF(Settings!$D$18=0,0,MAX(1,ROUND(Settings!$D$18*Settings!$C$5*($D9/Settings!$C$6)^Settings!$E$18*IF(Settings!$C$18="Lara",$E9/$F9,1),0)))) | AB9: =IF(Z9=0,0,IF(AA9=0,Z9,WORKDAY(Z9,1+Settings!$C$7,Settings!$J$4:$J$23))) | AC9: =IF(AB9=0,0,IF(AA9=0,AB9,WORKDAY(AB9,AA9-1,Settings!$J$4:$J$23))) | AD9: =IF($D9="",0,IF(Settings!$D$19=0,0,MAX(1,ROUND(Settings!$D$19*Settings!$C$5*($D9/Settings!$C$6)^Settings!$E$19*IF(Settings!$C$19="Lara",$E9/$F9,1),0)))) | AE9: =IF(AC9=0,0,IF(AD9=0,AC9,WORKDAY(AC9,1+Settings!$C$7,Settings!$J$4:$J$23))) | AF9: =IF(AE9=0,0,IF(AD9=0,AE9,WORKDAY(AE9,AD9-1,Settings!$J$4:$J$23))) | AG9: =AF9 | AH9: =IF($D9="",0,(I9*(Settings!$C$12="Lara")+L9*(Settings!$C$13="Lara")+O9*(Settings!$C$14="Lara")+R9*(Settings!$C$15="Lara")+U9*(Settings!$C$16="Lara")+X9*(Settings!$C$17="Lara")+AA9*(Settings!$C$18="Lara")+AD9*(Settings!$C$19="Lara"))*$F9*Settings!$C$4)
A10: 6 | B10: Example 06 | C10: Client F | D10: 120 | E10: 1.1 | F10: 0.4 | G10: 46398 | H10: Planned | I10: =IF($D10="",0,IF(Settings!$D$12=0,0,MAX(1,ROUND(Settings!$D$12*Settings!$C$5*($D10/Settings!$C$6)^Settings!$E$12*IF(Settings!$C$12="Lara",$E10/$F10,1),0)))) | J10: =IF($G10="",0,WORKDAY($G10-1,1,Settings!$J$4:$J$23)) | K10: =IF(J10=0,0,IF(I10=0,J10,WORKDAY(J10,I10-1,Settings!$J$4:$J$23))) | L10: =IF($D10="",0,IF(Settings!$D$13=0,0,MAX(1,ROUND(Settings!$D$13*Settings!$C$5*($D10/Settings!$C$6)^Settings!$E$13*IF(Settings!$C$13="Lara",$E10/$F10,1),0)))) | M10: =IF(K10=0,0,IF(L10=0,K10,WORKDAY(K10,1+Settings!$C$7,Settings!$J$4:$J$23))) | N10: =IF(M10=0,0,IF(L10=0,M10,WORKDAY(M10,L10-1,Settings!$J$4:$J$23))) | O10: =IF($D10="",0,IF(Settings!$D$14=0,0,MAX(1,ROUND(Settings!$D$14*Settings!$C$5*($D10/Settings!$C$6)^Settings!$E$14*IF(Settings!$C$14="Lara",$E10/$F10,1),0)))) | P10: =IF(N10=0,0,IF(O10=0,N10,WORKDAY(N10,1+Settings!$C$7,Settings!$J$4:$J$23))) | Q10: =IF(P10=0,0,IF(O10=0,P10,WORKDAY(P10,O10-1,Settings!$J$4:$J$23))) | R10: =IF($D10="",0,IF(Settings!$D$15=0,0,MAX(1,ROUND(Settings!$D$15*Settings!$C$5*($D10/Settings!$C$6)^Settings!$E$15*IF(Settings!$C$15="Lara",$E10/$F10,1),0)))) | S10: =IF(Q10=0,0,IF(R10=0,Q10,WORKDAY(Q10,1+Settings!$C$7,Settings!$J$4:$J$23))) | T10: =IF(S10=0,0,IF(R10=0,S10,WORKDAY(S10,R10-1,Settings!$J$4:$J$23))) | U10: =IF($D10="",0,IF(Settings!$D$16=0,0,MAX(1,ROUND(Settings!$D$16*Settings!$C$5*($D10/Settings!$C$6)^Settings!$E$16*IF(Settings!$C$16="Lara",$E10/$F10,1),0)))) | V10: =IF(T10=0,0,IF(U10=0,T10,WORKDAY(T10,1+Settings!$C$7,Settings!$J$4:$J$23))) | W10: =IF(V10=0,0,IF(U10=0,V10,WORKDAY(V10,U10-1,Settings!$J$4:$J$23))) | X10: =IF($D10="",0,IF(Settings!$D$17=0,0,MAX(1,ROUND(Settings!$D$17*Settings!$C$5*($D10/Settings!$C$6)^Settings!$E$17*IF(Settings!$C$17="Lara",$E10/$F10,1),0)))) | Y10: =IF(W10=0,0,IF(X10=0,W10,WORKDAY(W10,1+Settings!$C$7,Settings!$J$4:$J$23))) | Z10: =IF(Y10=0,0,IF(X10=0,Y10,WORKDAY(Y10,X10-1,Settings!$J$4:$J$23))) | AA10: =IF($D10="",0,IF(Settings!$D$18=0,0,MAX(1,ROUND(Settings!$D$18*Settings!$C$5*($D10/Settings!$C$6)^Settings!$E$18*IF(Settings!$C$18="Lara",$E10/$F10,1),0)))) | AB10: =IF(Z10=0,0,IF(AA10=0,Z10,WORKDAY(Z10,1+Settings!$C$7,Settings!$J$4:$J$23))) | AC10: =IF(AB10=0,0,IF(AA10=0,AB10,WORKDAY(AB10,AA10-1,Settings!$J$4:$J$23))) | AD10: =IF($D10="",0,IF(Settings!$D$19=0,0,MAX(1,ROUND(Settings!$D$19*Settings!$C$5*($D10/Settings!$C$6)^Settings!$E$19*IF(Settings!$C$19="Lara",$E10/$F10,1),0)))) | AE10: =IF(AC10=0,0,IF(AD10=0,AC10,WORKDAY(AC10,1+Settings!$C$7,Settings!$J$4:$J$23))) | AF10: =IF(AE10=0,0,IF(AD10=0,AE10,WORKDAY(AE10,AD10-1,Settings!$J$4:$J$23))) | AG10: =AF10 | AH10: =IF($D10="",0,(I10*(Settings!$C$12="Lara")+L10*(Settings!$C$13="Lara")+O10*(Settings!$C$14="Lara")+R10*(Settings!$C$15="Lara")+U10*(Settings!$C$16="Lara")+X10*(Settings!$C$17="Lara")+AA10*(Settings!$C$18="Lara")+AD10*(Settings!$C$19="Lara"))*$F10*Settings!$C$4) | AI10: House, runs in the background
A11: 7 | I11: =IF($D11="",0,IF(Settings!$D$12=0,0,MAX(1,ROUND(Settings!$D$12*Settings!$C$5*($D11/Settings!$C$6)^Settings!$E$12*IF(Settings!$C$12="Lara",$E11/$F11,1),0)))) | J11: =IF($G11="",0,WORKDAY($G11-1,1,Settings!$J$4:$J$23)) | K11: =IF(J11=0,0,IF(I11=0,J11,WORKDAY(J11,I11-1,Settings!$J$4:$J$23))) | L11: =IF($D11="",0,IF(Settings!$D$13=0,0,MAX(1,ROUND(Settings!$D$13*Settings!$C$5*($D11/Settings!$C$6)^Settings!$E$13*IF(Settings!$C$13="Lara",$E11/$F11,1),0)))) | M11: =IF(K11=0,0,IF(L11=0,K11,WORKDAY(K11,1+Settings!$C$7,Settings!$J$4:$J$23))) | N11: =IF(M11=0,0,IF(L11=0,M11,WORKDAY(M11,L11-1,Settings!$J$4:$J$23))) | O11: =IF($D11="",0,IF(Settings!$D$14=0,0,MAX(1,ROUND(Settings!$D$14*Settings!$C$5*($D11/Settings!$C$6)^Settings!$E$14*IF(Settings!$C$14="Lara",$E11/$F11,1),0)))) | P11: =IF(N11=0,0,IF(O11=0,N11,WORKDAY(N11,1+Settings!$C$7,Settings!$J$4:$J$23))) | Q11: =IF(P11=0,0,IF(O11=0,P11,WORKDAY(P11,O11-1,Settings!$J$4:$J$23))) | R11: =IF($D11="",0,IF(Settings!$D$15=0,0,MAX(1,ROUND(Settings!$D$15*Settings!$C$5*($D11/Settings!$C$6)^Settings!$E$15*IF(Settings!$C$15="Lara",$E11/$F11,1),0)))) | S11: =IF(Q11=0,0,IF(R11=0,Q11,WORKDAY(Q11,1+Settings!$C$7,Settings!$J$4:$J$23))) | T11: =IF(S11=0,0,IF(R11=0,S11,WORKDAY(S11,R11-1,Settings!$J$4:$J$23))) | U11: =IF($D11="",0,IF(Settings!$D$16=0,0,MAX(1,ROUND(Settings!$D$16*Settings!$C$5*($D11/Settings!$C$6)^Settings!$E$16*IF(Settings!$C$16="Lara",$E11/$F11,1),0)))) | V11: =IF(T11=0,0,IF(U11=0,T11,WORKDAY(T11,1+Settings!$C$7,Settings!$J$4:$J$23))) | W11: =IF(V11=0,0,IF(U11=0,V11,WORKDAY(V11,U11-1,Settings!$J$4:$J$23))) | X11: =IF($D11="",0,IF(Settings!$D$17=0,0,MAX(1,ROUND(Settings!$D$17*Settings!$C$5*($D11/Settings!$C$6)^Settings!$E$17*IF(Settings!$C$17="Lara",$E11/$F11,1),0)))) | Y11: =IF(W11=0,0,IF(X11=0,W11,WORKDAY(W11,1+Settings!$C$7,Settings!$J$4:$J$23))) | Z11: =IF(Y11=0,0,IF(X11=0,Y11,WORKDAY(Y11,X11-1,Settings!$J$4:$J$23))) | AA11: =IF($D11="",0,IF(Settings!$D$18=0,0,MAX(1,ROUND(Settings!$D$18*Settings!$C$5*($D11/Settings!$C$6)^Settings!$E$18*IF(Settings!$C$18="Lara",$E11/$F11,1),0)))) | AB11: =IF(Z11=0,0,IF(AA11=0,Z11,WORKDAY(Z11,1+Settings!$C$7,Settings!$J$4:$J$23))) | AC11: =IF(AB11=0,0,IF(AA11=0,AB11,WORKDAY(AB11,AA11-1,Settings!$J$4:$J$23))) | AD11: =IF($D11="",0,IF(Settings!$D$19=0,0,MAX(1,ROUND(Settings!$D$19*Settings!$C$5*($D11/Settings!$C$6)^Settings!$E$19*IF(Settings!$C$19="Lara",$E11/$F11,1),0)))) | AE11: =IF(AC11=0,0,IF(AD11=0,AC11,WORKDAY(AC11,1+Settings!$C$7,Settings!$J$4:$J$23))) | AF11: =IF(AE11=0,0,IF(AD11=0,AE11,WORKDAY(AE11,AD11-1,Settings!$J$4:$J$23))) | AG11: =AF11 | AH11: =IF($D11="",0,(I11*(Settings!$C$12="Lara")+L11*(Settings!$C$13="Lara")+O11*(Settings!$C$14="Lara")+R11*(Settings!$C$15="Lara")+U11*(Settings!$C$16="Lara")+X11*(Settings!$C$17="Lara")+AA11*(Settings!$C$18="Lara")+AD11*(Settings!$C$19="Lara"))*$F11*Settings!$C$4)
A12: 8 | I12: =IF($D12="",0,IF(Settings!$D$12=0,0,MAX(1,ROUND(Settings!$D$12*Settings!$C$5*($D12/Settings!$C$6)^Settings!$E$12*IF(Settings!$C$12="Lara",$E12/$F12,1),0)))) | J12: =IF($G12="",0,WORKDAY($G12-1,1,Settings!$J$4:$J$23)) | K12: =IF(J12=0,0,IF(I12=0,J12,WORKDAY(J12,I12-1,Settings!$J$4:$J$23))) | L12: =IF($D12="",0,IF(Settings!$D$13=0,0,MAX(1,ROUND(Settings!$D$13*Settings!$C$5*($D12/Settings!$C$6)^Settings!$E$13*IF(Settings!$C$13="Lara",$E12/$F12,1),0)))) | M12: =IF(K12=0,0,IF(L12=0,K12,WORKDAY(K12,1+Settings!$C$7,Settings!$J$4:$J$23))) | N12: =IF(M12=0,0,IF(L12=0,M12,WORKDAY(M12,L12-1,Settings!$J$4:$J$23))) | O12: =IF($D12="",0,IF(Settings!$D$14=0,0,MAX(1,ROUND(Settings!$D$14*Settings!$C$5*($D12/Settings!$C$6)^Settings!$E$14*IF(Settings!$C$14="Lara",$E12/$F12,1),0)))) | P12: =IF(N12=0,0,IF(O12=0,N12,WORKDAY(N12,1+Settings!$C$7,Settings!$J$4:$J$23))) | Q12: =IF(P12=0,0,IF(O12=0,P12,WORKDAY(P12,O12-1,Settings!$J$4:$J$23))) | R12: =IF($D12="",0,IF(Settings!$D$15=0,0,MAX(1,ROUND(Settings!$D$15*Settings!$C$5*($D12/Settings!$C$6)^Settings!$E$15*IF(Settings!$C$15="Lara",$E12/$F12,1),0)))) | S12: =IF(Q12=0,0,IF(R12=0,Q12,WORKDAY(Q12,1+Settings!$C$7,Settings!$J$4:$J$23))) | T12: =IF(S12=0,0,IF(R12=0,S12,WORKDAY(S12,R12-1,Settings!$J$4:$J$23))) | U12: =IF($D12="",0,IF(Settings!$D$16=0,0,MAX(1,ROUND(Settings!$D$16*Settings!$C$5*($D12/Settings!$C$6)^Settings!$E$16*IF(Settings!$C$16="Lara",$E12/$F12,1),0)))) | V12: =IF(T12=0,0,IF(U12=0,T12,WORKDAY(T12,1+Settings!$C$7,Settings!$J$4:$J$23))) | W12: =IF(V12=0,0,IF(U12=0,V12,WORKDAY(V12,U12-1,Settings!$J$4:$J$23))) | X12: =IF($D12="",0,IF(Settings!$D$17=0,0,MAX(1,ROUND(Settings!$D$17*Settings!$C$5*($D12/Settings!$C$6)^Settings!$E$17*IF(Settings!$C$17="Lara",$E12/$F12,1),0)))) | Y12: =IF(W12=0,0,IF(X12=0,W12,WORKDAY(W12,1+Settings!$C$7,Settings!$J$4:$J$23))) | Z12: =IF(Y12=0,0,IF(X12=0,Y12,WORKDAY(Y12,X12-1,Settings!$J$4:$J$23))) | AA12: =IF($D12="",0,IF(Settings!$D$18=0,0,MAX(1,ROUND(Settings!$D$18*Settings!$C$5*($D12/Settings!$C$6)^Settings!$E$18*IF(Settings!$C$18="Lara",$E12/$F12,1),0)))) | AB12: =IF(Z12=0,0,IF(AA12=0,Z12,WORKDAY(Z12,1+Settings!$C$7,Settings!$J$4:$J$23))) | AC12: =IF(AB12=0,0,IF(AA12=0,AB12,WORKDAY(AB12,AA12-1,Settings!$J$4:$J$23))) | AD12: =IF($D12="",0,IF(Settings!$D$19=0,0,MAX(1,ROUND(Settings!$D$19*Settings!$C$5*($D12/Settings!$C$6)^Settings!$E$19*IF(Settings!$C$19="Lara",$E12/$F12,1),0)))) | AE12: =IF(AC12=0,0,IF(AD12=0,AC12,WORKDAY(AC12,1+Settings!$C$7,Settings!$J$4:$J$23))) | AF12: =IF(AE12=0,0,IF(AD12=0,AE12,WORKDAY(AE12,AD12-1,Settings!$J$4:$J$23))) | AG12: =AF12 | AH12: =IF($D12="",0,(I12*(Settings!$C$12="Lara")+L12*(Settings!$C$13="Lara")+O12*(Settings!$C$14="Lara")+R12*(Settings!$C$15="Lara")+U12*(Settings!$C$16="Lara")+X12*(Settings!$C$17="Lara")+AA12*(Settings!$C$18="Lara")+AD12*(Settings!$C$19="Lara"))*$F12*Settings!$C$4)
A13: 9 | I13: =IF($D13="",0,IF(Settings!$D$12=0,0,MAX(1,ROUND(Settings!$D$12*Settings!$C$5*($D13/Settings!$C$6)^Settings!$E$12*IF(Settings!$C$12="Lara",$E13/$F13,1),0)))) | J13: =IF($G13="",0,WORKDAY($G13-1,1,Settings!$J$4:$J$23)) | K13: =IF(J13=0,0,IF(I13=0,J13,WORKDAY(J13,I13-1,Settings!$J$4:$J$23))) | L13: =IF($D13="",0,IF(Settings!$D$13=0,0,MAX(1,ROUND(Settings!$D$13*Settings!$C$5*($D13/Settings!$C$6)^Settings!$E$13*IF(Settings!$C$13="Lara",$E13/$F13,1),0)))) | M13: =IF(K13=0,0,IF(L13=0,K13,WORKDAY(K13,1+Settings!$C$7,Settings!$J$4:$J$23))) | N13: =IF(M13=0,0,IF(L13=0,M13,WORKDAY(M13,L13-1,Settings!$J$4:$J$23))) | O13: =IF($D13="",0,IF(Settings!$D$14=0,0,MAX(1,ROUND(Settings!$D$14*Settings!$C$5*($D13/Settings!$C$6)^Settings!$E$14*IF(Settings!$C$14="Lara",$E13/$F13,1),0)))) | P13: =IF(N13=0,0,IF(O13=0,N13,WORKDAY(N13,1+Settings!$C$7,Settings!$J$4:$J$23))) | Q13: =IF(P13=0,0,IF(O13=0,P13,WORKDAY(P13,O13-1,Settings!$J$4:$J$23))) | R13: =IF($D13="",0,IF(Settings!$D$15=0,0,MAX(1,ROUND(Settings!$D$15*Settings!$C$5*($D13/Settings!$C$6)^Settings!$E$15*IF(Settings!$C$15="Lara",$E13/$F13,1),0)))) | S13: =IF(Q13=0,0,IF(R13=0,Q13,WORKDAY(Q13,1+Settings!$C$7,Settings!$J$4:$J$23))) | T13: =IF(S13=0,0,IF(R13=0,S13,WORKDAY(S13,R13-1,Settings!$J$4:$J$23))) | U13: =IF($D13="",0,IF(Settings!$D$16=0,0,MAX(1,ROUND(Settings!$D$16*Settings!$C$5*($D13/Settings!$C$6)^Settings!$E$16*IF(Settings!$C$16="Lara",$E13/$F13,1),0)))) | V13: =IF(T13=0,0,IF(U13=0,T13,WORKDAY(T13,1+Settings!$C$7,Settings!$J$4:$J$23))) | W13: =IF(V13=0,0,IF(U13=0,V13,WORKDAY(V13,U13-1,Settings!$J$4:$J$23))) | X13: =IF($D13="",0,IF(Settings!$D$17=0,0,MAX(1,ROUND(Settings!$D$17*Settings!$C$5*($D13/Settings!$C$6)^Settings!$E$17*IF(Settings!$C$17="Lara",$E13/$F13,1),0)))) | Y13: =IF(W13=0,0,IF(X13=0,W13,WORKDAY(W13,1+Settings!$C$7,Settings!$J$4:$J$23))) | Z13: =IF(Y13=0,0,IF(X13=0,Y13,WORKDAY(Y13,X13-1,Settings!$J$4:$J$23))) | AA13: =IF($D13="",0,IF(Settings!$D$18=0,0,MAX(1,ROUND(Settings!$D$18*Settings!$C$5*($D13/Settings!$C$6)^Settings!$E$18*IF(Settings!$C$18="Lara",$E13/$F13,1),0)))) | AB13: =IF(Z13=0,0,IF(AA13=0,Z13,WORKDAY(Z13,1+Settings!$C$7,Settings!$J$4:$J$23))) | AC13: =IF(AB13=0,0,IF(AA13=0,AB13,WORKDAY(AB13,AA13-1,Settings!$J$4:$J$23))) | AD13: =IF($D13="",0,IF(Settings!$D$19=0,0,MAX(1,ROUND(Settings!$D$19*Settings!$C$5*($D13/Settings!$C$6)^Settings!$E$19*IF(Settings!$C$19="Lara",$E13/$F13,1),0)))) | AE13: =IF(AC13=0,0,IF(AD13=0,AC13,WORKDAY(AC13,1+Settings!$C$7,Settings!$J$4:$J$23))) | AF13: =IF(AE13=0,0,IF(AD13=0,AE13,WORKDAY(AE13,AD13-1,Settings!$J$4:$J$23))) | AG13: =AF13 | AH13: =IF($D13="",0,(I13*(Settings!$C$12="Lara")+L13*(Settings!$C$13="Lara")+O13*(Settings!$C$14="Lara")+R13*(Settings!$C$15="Lara")+U13*(Settings!$C$16="Lara")+X13*(Settings!$C$17="Lara")+AA13*(Settings!$C$18="Lara")+AD13*(Settings!$C$19="Lara"))*$F13*Settings!$C$4)
A14: 10 | I14: =IF($D14="",0,IF(Settings!$D$12=0,0,MAX(1,ROUND(Settings!$D$12*Settings!$C$5*($D14/Settings!$C$6)^Settings!$E$12*IF(Settings!$C$12="Lara",$E14/$F14,1),0)))) | J14: =IF($G14="",0,WORKDAY($G14-1,1,Settings!$J$4:$J$23)) | K14: =IF(J14=0,0,IF(I14=0,J14,WORKDAY(J14,I14-1,Settings!$J$4:$J$23))) | L14: =IF($D14="",0,IF(Settings!$D$13=0,0,MAX(1,ROUND(Settings!$D$13*Settings!$C$5*($D14/Settings!$C$6)^Settings!$E$13*IF(Settings!$C$13="Lara",$E14/$F14,1),0)))) | M14: =IF(K14=0,0,IF(L14=0,K14,WORKDAY(K14,1+Settings!$C$7,Settings!$J$4:$J$23))) | N14: =IF(M14=0,0,IF(L14=0,M14,WORKDAY(M14,L14-1,Settings!$J$4:$J$23))) | O14: =IF($D14="",0,IF(Settings!$D$14=0,0,MAX(1,ROUND(Settings!$D$14*Settings!$C$5*($D14/Settings!$C$6)^Settings!$E$14*IF(Settings!$C$14="Lara",$E14/$F14,1),0)))) | P14: =IF(N14=0,0,IF(O14=0,N14,WORKDAY(N14,1+Settings!$C$7,Settings!$J$4:$J$23))) | Q14: =IF(P14=0,0,IF(O14=0,P14,WORKDAY(P14,O14-1,Settings!$J$4:$J$23))) | R14: =IF($D14="",0,IF(Settings!$D$15=0,0,MAX(1,ROUND(Settings!$D$15*Settings!$C$5*($D14/Settings!$C$6)^Settings!$E$15*IF(Settings!$C$15="Lara",$E14/$F14,1),0)))) | S14: =IF(Q14=0,0,IF(R14=0,Q14,WORKDAY(Q14,1+Settings!$C$7,Settings!$J$4:$J$23))) | T14: =IF(S14=0,0,IF(R14=0,S14,WORKDAY(S14,R14-1,Settings!$J$4:$J$23))) | U14: =IF($D14="",0,IF(Settings!$D$16=0,0,MAX(1,ROUND(Settings!$D$16*Settings!$C$5*($D14/Settings!$C$6)^Settings!$E$16*IF(Settings!$C$16="Lara",$E14/$F14,1),0)))) | V14: =IF(T14=0,0,IF(U14=0,T14,WORKDAY(T14,1+Settings!$C$7,Settings!$J$4:$J$23))) | W14: =IF(V14=0,0,IF(U14=0,V14,WORKDAY(V14,U14-1,Settings!$J$4:$J$23))) | X14: =IF($D14="",0,IF(Settings!$D$17=0,0,MAX(1,ROUND(Settings!$D$17*Settings!$C$5*($D14/Settings!$C$6)^Settings!$E$17*IF(Settings!$C$17="Lara",$E14/$F14,1),0)))) | Y14: =IF(W14=0,0,IF(X14=0,W14,WORKDAY(W14,1+Settings!$C$7,Settings!$J$4:$J$23))) | Z14: =IF(Y14=0,0,IF(X14=0,Y14,WORKDAY(Y14,X14-1,Settings!$J$4:$J$23))) | AA14: =IF($D14="",0,IF(Settings!$D$18=0,0,MAX(1,ROUND(Settings!$D$18*Settings!$C$5*($D14/Settings!$C$6)^Settings!$E$18*IF(Settings!$C$18="Lara",$E14/$F14,1),0)))) | AB14: =IF(Z14=0,0,IF(AA14=0,Z14,WORKDAY(Z14,1+Settings!$C$7,Settings!$J$4:$J$23))) | AC14: =IF(AB14=0,0,IF(AA14=0,AB14,WORKDAY(AB14,AA14-1,Settings!$J$4:$J$23))) | AD14: =IF($D14="",0,IF(Settings!$D$19=0,0,MAX(1,ROUND(Settings!$D$19*Settings!$C$5*($D14/Settings!$C$6)^Settings!$E$19*IF(Settings!$C$19="Lara",$E14/$F14,1),0)))) | AE14: =IF(AC14=0,0,IF(AD14=0,AC14,WORKDAY(AC14,1+Settings!$C$7,Settings!$J$4:$J$23))) | AF14: =IF(AE14=0,0,IF(AD14=0,AE14,WORKDAY(AE14,AD14-1,Settings!$J$4:$J$23))) | AG14: =AF14 | AH14: =IF($D14="",0,(I14*(Settings!$C$12="Lara")+L14*(Settings!$C$13="Lara")+O14*(Settings!$C$14="Lara")+R14*(Settings!$C$15="Lara")+U14*(Settings!$C$16="Lara")+X14*(Settings!$C$17="Lara")+AA14*(Settings!$C$18="Lara")+AD14*(Settings!$C$19="Lara"))*$F14*Settings!$C$4)
A15: 11 | I15: =IF($D15="",0,IF(Settings!$D$12=0,0,MAX(1,ROUND(Settings!$D$12*Settings!$C$5*($D15/Settings!$C$6)^Settings!$E$12*IF(Settings!$C$12="Lara",$E15/$F15,1),0)))) | J15: =IF($G15="",0,WORKDAY($G15-1,1,Settings!$J$4:$J$23)) | K15: =IF(J15=0,0,IF(I15=0,J15,WORKDAY(J15,I15-1,Settings!$J$4:$J$23))) | L15: =IF($D15="",0,IF(Settings!$D$13=0,0,MAX(1,ROUND(Settings!$D$13*Settings!$C$5*($D15/Settings!$C$6)^Settings!$E$13*IF(Settings!$C$13="Lara",$E15/$F15,1),0)))) | M15: =IF(K15=0,0,IF(L15=0,K15,WORKDAY(K15,1+Settings!$C$7,Settings!$J$4:$J$23))) | N15: =IF(M15=0,0,IF(L15=0,M15,WORKDAY(M15,L15-1,Settings!$J$4:$J$23))) | O15: =IF($D15="",0,IF(Settings!$D$14=0,0,MAX(1,ROUND(Settings!$D$14*Settings!$C$5*($D15/Settings!$C$6)^Settings!$E$14*IF(Settings!$C$14="Lara",$E15/$F15,1),0)))) | P15: =IF(N15=0,0,IF(O15=0,N15,WORKDAY(N15,1+Settings!$C$7,Settings!$J$4:$J$23))) | Q15: =IF(P15=0,0,IF(O15=0,P15,WORKDAY(P15,O15-1,Settings!$J$4:$J$23))) | R15: =IF($D15="",0,IF(Settings!$D$15=0,0,MAX(1,ROUND(Settings!$D$15*Settings!$C$5*($D15/Settings!$C$6)^Settings!$E$15*IF(Settings!$C$15="Lara",$E15/$F15,1),0)))) | S15: =IF(Q15=0,0,IF(R15=0,Q15,WORKDAY(Q15,1+Settings!$C$7,Settings!$J$4:$J$23))) | T15: =IF(S15=0,0,IF(R15=0,S15,WORKDAY(S15,R15-1,Settings!$J$4:$J$23))) | U15: =IF($D15="",0,IF(Settings!$D$16=0,0,MAX(1,ROUND(Settings!$D$16*Settings!$C$5*($D15/Settings!$C$6)^Settings!$E$16*IF(Settings!$C$16="Lara",$E15/$F15,1),0)))) | V15: =IF(T15=0,0,IF(U15=0,T15,WORKDAY(T15,1+Settings!$C$7,Settings!$J$4:$J$23))) | W15: =IF(V15=0,0,IF(U15=0,V15,WORKDAY(V15,U15-1,Settings!$J$4:$J$23))) | X15: =IF($D15="",0,IF(Settings!$D$17=0,0,MAX(1,ROUND(Settings!$D$17*Settings!$C$5*($D15/Settings!$C$6)^Settings!$E$17*IF(Settings!$C$17="Lara",$E15/$F15,1),0)))) | Y15: =IF(W15=0,0,IF(X15=0,W15,WORKDAY(W15,1+Settings!$C$7,Settings!$J$4:$J$23))) | Z15: =IF(Y15=0,0,IF(X15=0,Y15,WORKDAY(Y15,X15-1,Settings!$J$4:$J$23))) | AA15: =IF($D15="",0,IF(Settings!$D$18=0,0,MAX(1,ROUND(Settings!$D$18*Settings!$C$5*($D15/Settings!$C$6)^Settings!$E$18*IF(Settings!$C$18="Lara",$E15/$F15,1),0)))) | AB15: =IF(Z15=0,0,IF(AA15=0,Z15,WORKDAY(Z15,1+Settings!$C$7,Settings!$J$4:$J$23))) | AC15: =IF(AB15=0,0,IF(AA15=0,AB15,WORKDAY(AB15,AA15-1,Settings!$J$4:$J$23))) | AD15: =IF($D15="",0,IF(Settings!$D$19=0,0,MAX(1,ROUND(Settings!$D$19*Settings!$C$5*($D15/Settings!$C$6)^Settings!$E$19*IF(Settings!$C$19="Lara",$E15/$F15,1),0)))) | AE15: =IF(AC15=0,0,IF(AD15=0,AC15,WORKDAY(AC15,1+Settings!$C$7,Settings!$J$4:$J$23))) | AF15: =IF(AE15=0,0,IF(AD15=0,AE15,WORKDAY(AE15,AD15-1,Settings!$J$4:$J$23))) | AG15: =AF15 | AH15: =IF($D15="",0,(I15*(Settings!$C$12="Lara")+L15*(Settings!$C$13="Lara")+O15*(Settings!$C$14="Lara")+R15*(Settings!$C$15="Lara")+U15*(Settings!$C$16="Lara")+X15*(Settings!$C$17="Lara")+AA15*(Settings!$C$18="Lara")+AD15*(Settings!$C$19="Lara"))*$F15*Settings!$C$4)
A16: 12 | I16: =IF($D16="",0,IF(Settings!$D$12=0,0,MAX(1,ROUND(Settings!$D$12*Settings!$C$5*($D16/Settings!$C$6)^Settings!$E$12*IF(Settings!$C$12="Lara",$E16/$F16,1),0)))) | J16: =IF($G16="",0,WORKDAY($G16-1,1,Settings!$J$4:$J$23)) | K16: =IF(J16=0,0,IF(I16=0,J16,WORKDAY(J16,I16-1,Settings!$J$4:$J$23))) | L16: =IF($D16="",0,IF(Settings!$D$13=0,0,MAX(1,ROUND(Settings!$D$13*Settings!$C$5*($D16/Settings!$C$6)^Settings!$E$13*IF(Settings!$C$13="Lara",$E16/$F16,1),0)))) | M16: =IF(K16=0,0,IF(L16=0,K16,WORKDAY(K16,1+Settings!$C$7,Settings!$J$4:$J$23))) | N16: =IF(M16=0,0,IF(L16=0,M16,WORKDAY(M16,L16-1,Settings!$J$4:$J$23))) | O16: =IF($D16="",0,IF(Settings!$D$14=0,0,MAX(1,ROUND(Settings!$D$14*Settings!$C$5*($D16/Settings!$C$6)^Settings!$E$14*IF(Settings!$C$14="Lara",$E16/$F16,1),0)))) | P16: =IF(N16=0,0,IF(O16=0,N16,WORKDAY(N16,1+Settings!$C$7,Settings!$J$4:$J$23))) | Q16: =IF(P16=0,0,IF(O16=0,P16,WORKDAY(P16,O16-1,Settings!$J$4:$J$23))) | R16: =IF($D16="",0,IF(Settings!$D$15=0,0,MAX(1,ROUND(Settings!$D$15*Settings!$C$5*($D16/Settings!$C$6)^Settings!$E$15*IF(Settings!$C$15="Lara",$E16/$F16,1),0)))) | S16: =IF(Q16=0,0,IF(R16=0,Q16,WORKDAY(Q16,1+Settings!$C$7,Settings!$J$4:$J$23))) | T16: =IF(S16=0,0,IF(R16=0,S16,WORKDAY(S16,R16-1,Settings!$J$4:$J$23))) | U16: =IF($D16="",0,IF(Settings!$D$16=0,0,MAX(1,ROUND(Settings!$D$16*Settings!$C$5*($D16/Settings!$C$6)^Settings!$E$16*IF(Settings!$C$16="Lara",$E16/$F16,1),0)))) | V16: =IF(T16=0,0,IF(U16=0,T16,WORKDAY(T16,1+Settings!$C$7,Settings!$J$4:$J$23))) | W16: =IF(V16=0,0,IF(U16=0,V16,WORKDAY(V16,U16-1,Settings!$J$4:$J$23))) | X16: =IF($D16="",0,IF(Settings!$D$17=0,0,MAX(1,ROUND(Settings!$D$17*Settings!$C$5*($D16/Settings!$C$6)^Settings!$E$17*IF(Settings!$C$17="Lara",$E16/$F16,1),0)))) | Y16: =IF(W16=0,0,IF(X16=0,W16,WORKDAY(W16,1+Settings!$C$7,Settings!$J$4:$J$23))) | Z16: =IF(Y16=0,0,IF(X16=0,Y16,WORKDAY(Y16,X16-1,Settings!$J$4:$J$23))) | AA16: =IF($D16="",0,IF(Settings!$D$18=0,0,MAX(1,ROUND(Settings!$D$18*Settings!$C$5*($D16/Settings!$C$6)^Settings!$E$18*IF(Settings!$C$18="Lara",$E16/$F16,1),0)))) | AB16: =IF(Z16=0,0,IF(AA16=0,Z16,WORKDAY(Z16,1+Settings!$C$7,Settings!$J$4:$J$23))) | AC16: =IF(AB16=0,0,IF(AA16=0,AB16,WORKDAY(AB16,AA16-1,Settings!$J$4:$J$23))) | AD16: =IF($D16="",0,IF(Settings!$D$19=0,0,MAX(1,ROUND(Settings!$D$19*Settings!$C$5*($D16/Settings!$C$6)^Settings!$E$19*IF(Settings!$C$19="Lara",$E16/$F16,1),0)))) | AE16: =IF(AC16=0,0,IF(AD16=0,AC16,WORKDAY(AC16,1+Settings!$C$7,Settings!$J$4:$J$23))) | AF16: =IF(AE16=0,0,IF(AD16=0,AE16,WORKDAY(AE16,AD16-1,Settings!$J$4:$J$23))) | AG16: =AF16 | AH16: =IF($D16="",0,(I16*(Settings!$C$12="Lara")+L16*(Settings!$C$13="Lara")+O16*(Settings!$C$14="Lara")+R16*(Settings!$C$15="Lara")+U16*(Settings!$C$16="Lara")+X16*(Settings!$C$17="Lara")+AA16*(Settings!$C$18="Lara")+AD16*(Settings!$C$19="Lara"))*$F16*Settings!$C$4)
A17: 13 | I17: =IF($D17="",0,IF(Settings!$D$12=0,0,MAX(1,ROUND(Settings!$D$12*Settings!$C$5*($D17/Settings!$C$6)^Settings!$E$12*IF(Settings!$C$12="Lara",$E17/$F17,1),0)))) | J17: =IF($G17="",0,WORKDAY($G17-1,1,Settings!$J$4:$J$23)) | K17: =IF(J17=0,0,IF(I17=0,J17,WORKDAY(J17,I17-1,Settings!$J$4:$J$23))) | L17: =IF($D17="",0,IF(Settings!$D$13=0,0,MAX(1,ROUND(Settings!$D$13*Settings!$C$5*($D17/Settings!$C$6)^Settings!$E$13*IF(Settings!$C$13="Lara",$E17/$F17,1),0)))) | M17: =IF(K17=0,0,IF(L17=0,K17,WORKDAY(K17,1+Settings!$C$7,Settings!$J$4:$J$23))) | N17: =IF(M17=0,0,IF(L17=0,M17,WORKDAY(M17,L17-1,Settings!$J$4:$J$23))) | O17: =IF($D17="",0,IF(Settings!$D$14=0,0,MAX(1,ROUND(Settings!$D$14*Settings!$C$5*($D17/Settings!$C$6)^Settings!$E$14*IF(Settings!$C$14="Lara",$E17/$F17,1),0)))) | P17: =IF(N17=0,0,IF(O17=0,N17,WORKDAY(N17,1+Settings!$C$7,Settings!$J$4:$J$23))) | Q17: =IF(P17=0,0,IF(O17=0,P17,WORKDAY(P17,O17-1,Settings!$J$4:$J$23))) | R17: =IF($D17="",0,IF(Settings!$D$15=0,0,MAX(1,ROUND(Settings!$D$15*Settings!$C$5*($D17/Settings!$C$6)^Settings!$E$15*IF(Settings!$C$15="Lara",$E17/$F17,1),0)))) | S17: =IF(Q17=0,0,IF(R17=0,Q17,WORKDAY(Q17,1+Settings!$C$7,Settings!$J$4:$J$23))) | T17: =IF(S17=0,0,IF(R17=0,S17,WORKDAY(S17,R17-1,Settings!$J$4:$J$23))) | U17: =IF($D17="",0,IF(Settings!$D$16=0,0,MAX(1,ROUND(Settings!$D$16*Settings!$C$5*($D17/Settings!$C$6)^Settings!$E$16*IF(Settings!$C$16="Lara",$E17/$F17,1),0)))) | V17: =IF(T17=0,0,IF(U17=0,T17,WORKDAY(T17,1+Settings!$C$7,Settings!$J$4:$J$23))) | W17: =IF(V17=0,0,IF(U17=0,V17,WORKDAY(V17,U17-1,Settings!$J$4:$J$23))) | X17: =IF($D17="",0,IF(Settings!$D$17=0,0,MAX(1,ROUND(Settings!$D$17*Settings!$C$5*($D17/Settings!$C$6)^Settings!$E$17*IF(Settings!$C$17="Lara",$E17/$F17,1),0)))) | Y17: =IF(W17=0,0,IF(X17=0,W17,WORKDAY(W17,1+Settings!$C$7,Settings!$J$4:$J$23))) | Z17: =IF(Y17=0,0,IF(X17=0,Y17,WORKDAY(Y17,X17-1,Settings!$J$4:$J$23))) | AA17: =IF($D17="",0,IF(Settings!$D$18=0,0,MAX(1,ROUND(Settings!$D$18*Settings!$C$5*($D17/Settings!$C$6)^Settings!$E$18*IF(Settings!$C$18="Lara",$E17/$F17,1),0)))) | AB17: =IF(Z17=0,0,IF(AA17=0,Z17,WORKDAY(Z17,1+Settings!$C$7,Settings!$J$4:$J$23))) | AC17: =IF(AB17=0,0,IF(AA17=0,AB17,WORKDAY(AB17,AA17-1,Settings!$J$4:$J$23))) | AD17: =IF($D17="",0,IF(Settings!$D$19=0,0,MAX(1,ROUND(Settings!$D$19*Settings!$C$5*($D17/Settings!$C$6)^Settings!$E$19*IF(Settings!$C$19="Lara",$E17/$F17,1),0)))) | AE17: =IF(AC17=0,0,IF(AD17=0,AC17,WORKDAY(AC17,1+Settings!$C$7,Settings!$J$4:$J$23))) | AF17: =IF(AE17=0,0,IF(AD17=0,AE17,WORKDAY(AE17,AD17-1,Settings!$J$4:$J$23))) | AG17: =AF17 | AH17: =IF($D17="",0,(I17*(Settings!$C$12="Lara")+L17*(Settings!$C$13="Lara")+O17*(Settings!$C$14="Lara")+R17*(Settings!$C$15="Lara")+U17*(Settings!$C$16="Lara")+X17*(Settings!$C$17="Lara")+AA17*(Settings!$C$18="Lara")+AD17*(Settings!$C$19="Lara"))*$F17*Settings!$C$4)
A18: 14 | I18: =IF($D18="",0,IF(Settings!$D$12=0,0,MAX(1,ROUND(Settings!$D$12*Settings!$C$5*($D18/Settings!$C$6)^Settings!$E$12*IF(Settings!$C$12="Lara",$E18/$F18,1),0)))) | J18: =IF($G18="",0,WORKDAY($G18-1,1,Settings!$J$4:$J$23)) | K18: =IF(J18=0,0,IF(I18=0,J18,WORKDAY(J18,I18-1,Settings!$J$4:$J$23))) | L18: =IF($D18="",0,IF(Settings!$D$13=0,0,MAX(1,ROUND(Settings!$D$13*Settings!$C$5*($D18/Settings!$C$6)^Settings!$E$13*IF(Settings!$C$13="Lara",$E18/$F18,1),0)))) | M18: =IF(K18=0,0,IF(L18=0,K18,WORKDAY(K18,1+Settings!$C$7,Settings!$J$4:$J$23))) | N18: =IF(M18=0,0,IF(L18=0,M18,WORKDAY(M18,L18-1,Settings!$J$4:$J$23))) | O18: =IF($D18="",0,IF(Settings!$D$14=0,0,MAX(1,ROUND(Settings!$D$14*Settings!$C$5*($D18/Settings!$C$6)^Settings!$E$14*IF(Settings!$C$14="Lara",$E18/$F18,1),0)))) | P18: =IF(N18=0,0,IF(O18=0,N18,WORKDAY(N18,1+Settings!$C$7,Settings!$J$4:$J$23))) | Q18: =IF(P18=0,0,IF(O18=0,P18,WORKDAY(P18,O18-1,Settings!$J$4:$J$23))) | R18: =IF($D18="",0,IF(Settings!$D$15=0,0,MAX(1,ROUND(Settings!$D$15*Settings!$C$5*($D18/Settings!$C$6)^Settings!$E$15*IF(Settings!$C$15="Lara",$E18/$F18,1),0)))) | S18: =IF(Q18=0,0,IF(R18=0,Q18,WORKDAY(Q18,1+Settings!$C$7,Settings!$J$4:$J$23))) | T18: =IF(S18=0,0,IF(R18=0,S18,WORKDAY(S18,R18-1,Settings!$J$4:$J$23))) | U18: =IF($D18="",0,IF(Settings!$D$16=0,0,MAX(1,ROUND(Settings!$D$16*Settings!$C$5*($D18/Settings!$C$6)^Settings!$E$16*IF(Settings!$C$16="Lara",$E18/$F18,1),0)))) | V18: =IF(T18=0,0,IF(U18=0,T18,WORKDAY(T18,1+Settings!$C$7,Settings!$J$4:$J$23))) | W18: =IF(V18=0,0,IF(U18=0,V18,WORKDAY(V18,U18-1,Settings!$J$4:$J$23))) | X18: =IF($D18="",0,IF(Settings!$D$17=0,0,MAX(1,ROUND(Settings!$D$17*Settings!$C$5*($D18/Settings!$C$6)^Settings!$E$17*IF(Settings!$C$17="Lara",$E18/$F18,1),0)))) | Y18: =IF(W18=0,0,IF(X18=0,W18,WORKDAY(W18,1+Settings!$C$7,Settings!$J$4:$J$23))) | Z18: =IF(Y18=0,0,IF(X18=0,Y18,WORKDAY(Y18,X18-1,Settings!$J$4:$J$23))) | AA18: =IF($D18="",0,IF(Settings!$D$18=0,0,MAX(1,ROUND(Settings!$D$18*Settings!$C$5*($D18/Settings!$C$6)^Settings!$E$18*IF(Settings!$C$18="Lara",$E18/$F18,1),0)))) | AB18: =IF(Z18=0,0,IF(AA18=0,Z18,WORKDAY(Z18,1+Settings!$C$7,Settings!$J$4:$J$23))) | AC18: =IF(AB18=0,0,IF(AA18=0,AB18,WORKDAY(AB18,AA18-1,Settings!$J$4:$J$23))) | AD18: =IF($D18="",0,IF(Settings!$D$19=0,0,MAX(1,ROUND(Settings!$D$19*Settings!$C$5*($D18/Settings!$C$6)^Settings!$E$19*IF(Settings!$C$19="Lara",$E18/$F18,1),0)))) | AE18: =IF(AC18=0,0,IF(AD18=0,AC18,WORKDAY(AC18,1+Settings!$C$7,Settings!$J$4:$J$23))) | AF18: =IF(AE18=0,0,IF(AD18=0,AE18,WORKDAY(AE18,AD18-1,Settings!$J$4:$J$23))) | AG18: =AF18 | AH18: =IF($D18="",0,(I18*(Settings!$C$12="Lara")+L18*(Settings!$C$13="Lara")+O18*(Settings!$C$14="Lara")+R18*(Settings!$C$15="Lara")+U18*(Settings!$C$16="Lara")+X18*(Settings!$C$17="Lara")+AA18*(Settings!$C$18="Lara")+AD18*(Settings!$C$19="Lara"))*$F18*Settings!$C$4)
A19: 15 | I19: =IF($D19="",0,IF(Settings!$D$12=0,0,MAX(1,ROUND(Settings!$D$12*Settings!$C$5*($D19/Settings!$C$6)^Settings!$E$12*IF(Settings!$C$12="Lara",$E19/$F19,1),0)))) | J19: =IF($G19="",0,WORKDAY($G19-1,1,Settings!$J$4:$J$23)) | K19: =IF(J19=0,0,IF(I19=0,J19,WORKDAY(J19,I19-1,Settings!$J$4:$J$23))) | L19: =IF($D19="",0,IF(Settings!$D$13=0,0,MAX(1,ROUND(Settings!$D$13*Settings!$C$5*($D19/Settings!$C$6)^Settings!$E$13*IF(Settings!$C$13="Lara",$E19/$F19,1),0)))) | M19: =IF(K19=0,0,IF(L19=0,K19,WORKDAY(K19,1+Settings!$C$7,Settings!$J$4:$J$23))) | N19: =IF(M19=0,0,IF(L19=0,M19,WORKDAY(M19,L19-1,Settings!$J$4:$J$23))) | O19: =IF($D19="",0,IF(Settings!$D$14=0,0,MAX(1,ROUND(Settings!$D$14*Settings!$C$5*($D19/Settings!$C$6)^Settings!$E$14*IF(Settings!$C$14="Lara",$E19/$F19,1),0)))) | P19: =IF(N19=0,0,IF(O19=0,N19,WORKDAY(N19,1+Settings!$C$7,Settings!$J$4:$J$23))) | Q19: =IF(P19=0,0,IF(O19=0,P19,WORKDAY(P19,O19-1,Settings!$J$4:$J$23))) | R19: =IF($D19="",0,IF(Settings!$D$15=0,0,MAX(1,ROUND(Settings!$D$15*Settings!$C$5*($D19/Settings!$C$6)^Settings!$E$15*IF(Settings!$C$15="Lara",$E19/$F19,1),0)))) | S19: =IF(Q19=0,0,IF(R19=0,Q19,WORKDAY(Q19,1+Settings!$C$7,Settings!$J$4:$J$23))) | T19: =IF(S19=0,0,IF(R19=0,S19,WORKDAY(S19,R19-1,Settings!$J$4:$J$23))) | U19: =IF($D19="",0,IF(Settings!$D$16=0,0,MAX(1,ROUND(Settings!$D$16*Settings!$C$5*($D19/Settings!$C$6)^Settings!$E$16*IF(Settings!$C$16="Lara",$E19/$F19,1),0)))) | V19: =IF(T19=0,0,IF(U19=0,T19,WORKDAY(T19,1+Settings!$C$7,Settings!$J$4:$J$23))) | W19: =IF(V19=0,0,IF(U19=0,V19,WORKDAY(V19,U19-1,Settings!$J$4:$J$23))) | X19: =IF($D19="",0,IF(Settings!$D$17=0,0,MAX(1,ROUND(Settings!$D$17*Settings!$C$5*($D19/Settings!$C$6)^Settings!$E$17*IF(Settings!$C$17="Lara",$E19/$F19,1),0)))) | Y19: =IF(W19=0,0,IF(X19=0,W19,WORKDAY(W19,1+Settings!$C$7,Settings!$J$4:$J$23))) | Z19: =IF(Y19=0,0,IF(X19=0,Y19,WORKDAY(Y19,X19-1,Settings!$J$4:$J$23))) | AA19: =IF($D19="",0,IF(Settings!$D$18=0,0,MAX(1,ROUND(Settings!$D$18*Settings!$C$5*($D19/Settings!$C$6)^Settings!$E$18*IF(Settings!$C$18="Lara",$E19/$F19,1),0)))) | AB19: =IF(Z19=0,0,IF(AA19=0,Z19,WORKDAY(Z19,1+Settings!$C$7,Settings!$J$4:$J$23))) | AC19: =IF(AB19=0,0,IF(AA19=0,AB19,WORKDAY(AB19,AA19-1,Settings!$J$4:$J$23))) | AD19: =IF($D19="",0,IF(Settings!$D$19=0,0,MAX(1,ROUND(Settings!$D$19*Settings!$C$5*($D19/Settings!$C$6)^Settings!$E$19*IF(Settings!$C$19="Lara",$E19/$F19,1),0)))) | AE19: =IF(AC19=0,0,IF(AD19=0,AC19,WORKDAY(AC19,1+Settings!$C$7,Settings!$J$4:$J$23))) | AF19: =IF(AE19=0,0,IF(AD19=0,AE19,WORKDAY(AE19,AD19-1,Settings!$J$4:$J$23))) | AG19: =AF19 | AH19: =IF($D19="",0,(I19*(Settings!$C$12="Lara")+L19*(Settings!$C$13="Lara")+O19*(Settings!$C$14="Lara")+R19*(Settings!$C$15="Lara")+U19*(Settings!$C$16="Lara")+X19*(Settings!$C$17="Lara")+AA19*(Settings!$C$18="Lara")+AD19*(Settings!$C$19="Lara"))*$F19*Settings!$C$4)
A20: 16 | I20: =IF($D20="",0,IF(Settings!$D$12=0,0,MAX(1,ROUND(Settings!$D$12*Settings!$C$5*($D20/Settings!$C$6)^Settings!$E$12*IF(Settings!$C$12="Lara",$E20/$F20,1),0)))) | J20: =IF($G20="",0,WORKDAY($G20-1,1,Settings!$J$4:$J$23)) | K20: =IF(J20=0,0,IF(I20=0,J20,WORKDAY(J20,I20-1,Settings!$J$4:$J$23))) | L20: =IF($D20="",0,IF(Settings!$D$13=0,0,MAX(1,ROUND(Settings!$D$13*Settings!$C$5*($D20/Settings!$C$6)^Settings!$E$13*IF(Settings!$C$13="Lara",$E20/$F20,1),0)))) | M20: =IF(K20=0,0,IF(L20=0,K20,WORKDAY(K20,1+Settings!$C$7,Settings!$J$4:$J$23))) | N20: =IF(M20=0,0,IF(L20=0,M20,WORKDAY(M20,L20-1,Settings!$J$4:$J$23))) | O20: =IF($D20="",0,IF(Settings!$D$14=0,0,MAX(1,ROUND(Settings!$D$14*Settings!$C$5*($D20/Settings!$C$6)^Settings!$E$14*IF(Settings!$C$14="Lara",$E20/$F20,1),0)))) | P20: =IF(N20=0,0,IF(O20=0,N20,WORKDAY(N20,1+Settings!$C$7,Settings!$J$4:$J$23))) | Q20: =IF(P20=0,0,IF(O20=0,P20,WORKDAY(P20,O20-1,Settings!$J$4:$J$23))) | R20: =IF($D20="",0,IF(Settings!$D$15=0,0,MAX(1,ROUND(Settings!$D$15*Settings!$C$5*($D20/Settings!$C$6)^Settings!$E$15*IF(Settings!$C$15="Lara",$E20/$F20,1),0)))) | S20: =IF(Q20=0,0,IF(R20=0,Q20,WORKDAY(Q20,1+Settings!$C$7,Settings!$J$4:$J$23))) | T20: =IF(S20=0,0,IF(R20=0,S20,WORKDAY(S20,R20-1,Settings!$J$4:$J$23))) | U20: =IF($D20="",0,IF(Settings!$D$16=0,0,MAX(1,ROUND(Settings!$D$16*Settings!$C$5*($D20/Settings!$C$6)^Settings!$E$16*IF(Settings!$C$16="Lara",$E20/$F20,1),0)))) | V20: =IF(T20=0,0,IF(U20=0,T20,WORKDAY(T20,1+Settings!$C$7,Settings!$J$4:$J$23))) | W20: =IF(V20=0,0,IF(U20=0,V20,WORKDAY(V20,U20-1,Settings!$J$4:$J$23))) | X20: =IF($D20="",0,IF(Settings!$D$17=0,0,MAX(1,ROUND(Settings!$D$17*Settings!$C$5*($D20/Settings!$C$6)^Settings!$E$17*IF(Settings!$C$17="Lara",$E20/$F20,1),0)))) | Y20: =IF(W20=0,0,IF(X20=0,W20,WORKDAY(W20,1+Settings!$C$7,Settings!$J$4:$J$23))) | Z20: =IF(Y20=0,0,IF(X20=0,Y20,WORKDAY(Y20,X20-1,Settings!$J$4:$J$23))) | AA20: =IF($D20="",0,IF(Settings!$D$18=0,0,MAX(1,ROUND(Settings!$D$18*Settings!$C$5*($D20/Settings!$C$6)^Settings!$E$18*IF(Settings!$C$18="Lara",$E20/$F20,1),0)))) | AB20: =IF(Z20=0,0,IF(AA20=0,Z20,WORKDAY(Z20,1+Settings!$C$7,Settings!$J$4:$J$23))) | AC20: =IF(AB20=0,0,IF(AA20=0,AB20,WORKDAY(AB20,AA20-1,Settings!$J$4:$J$23))) | AD20: =IF($D20="",0,IF(Settings!$D$19=0,0,MAX(1,ROUND(Settings!$D$19*Settings!$C$5*($D20/Settings!$C$6)^Settings!$E$19*IF(Settings!$C$19="Lara",$E20/$F20,1),0)))) | AE20: =IF(AC20=0,0,IF(AD20=0,AC20,WORKDAY(AC20,1+Settings!$C$7,Settings!$J$4:$J$23))) | AF20: =IF(AE20=0,0,IF(AD20=0,AE20,WORKDAY(AE20,AD20-1,Settings!$J$4:$J$23))) | AG20: =AF20 | AH20: =IF($D20="",0,(I20*(Settings!$C$12="Lara")+L20*(Settings!$C$13="Lara")+O20*(Settings!$C$14="Lara")+R20*(Settings!$C$15="Lara")+U20*(Settings!$C$16="Lara")+X20*(Settings!$C$17="Lara")+AA20*(Settings!$C$18="Lara")+AD20*(Settings!$C$19="Lara"))*$F20*Settings!$C$4)
A21: 17 | I21: =IF($D21="",0,IF(Settings!$D$12=0,0,MAX(1,ROUND(Settings!$D$12*Settings!$C$5*($D21/Settings!$C$6)^Settings!$E$12*IF(Settings!$C$12="Lara",$E21/$F21,1),0)))) | J21: =IF($G21="",0,WORKDAY($G21-1,1,Settings!$J$4:$J$23)) | K21: =IF(J21=0,0,IF(I21=0,J21,WORKDAY(J21,I21-1,Settings!$J$4:$J$23))) | L21: =IF($D21="",0,IF(Settings!$D$13=0,0,MAX(1,ROUND(Settings!$D$13*Settings!$C$5*($D21/Settings!$C$6)^Settings!$E$13*IF(Settings!$C$13="Lara",$E21/$F21,1),0)))) | M21: =IF(K21=0,0,IF(L21=0,K21,WORKDAY(K21,1+Settings!$C$7,Settings!$J$4:$J$23))) | N21: =IF(M21=0,0,IF(L21=0,M21,WORKDAY(M21,L21-1,Settings!$J$4:$J$23))) | O21: =IF($D21="",0,IF(Settings!$D$14=0,0,MAX(1,ROUND(Settings!$D$14*Settings!$C$5*($D21/Settings!$C$6)^Settings!$E$14*IF(Settings!$C$14="Lara",$E21/$F21,1),0)))) | P21: =IF(N21=0,0,IF(O21=0,N21,WORKDAY(N21,1+Settings!$C$7,Settings!$J$4:$J$23))) | Q21: =IF(P21=0,0,IF(O21=0,P21,WORKDAY(P21,O21-1,Settings!$J$4:$J$23))) | R21: =IF($D21="",0,IF(Settings!$D$15=0,0,MAX(1,ROUND(Settings!$D$15*Settings!$C$5*($D21/Settings!$C$6)^Settings!$E$15*IF(Settings!$C$15="Lara",$E21/$F21,1),0)))) | S21: =IF(Q21=0,0,IF(R21=0,Q21,WORKDAY(Q21,1+Settings!$C$7,Settings!$J$4:$J$23))) | T21: =IF(S21=0,0,IF(R21=0,S21,WORKDAY(S21,R21-1,Settings!$J$4:$J$23))) | U21: =IF($D21="",0,IF(Settings!$D$16=0,0,MAX(1,ROUND(Settings!$D$16*Settings!$C$5*($D21/Settings!$C$6)^Settings!$E$16*IF(Settings!$C$16="Lara",$E21/$F21,1),0)))) | V21: =IF(T21=0,0,IF(U21=0,T21,WORKDAY(T21,1+Settings!$C$7,Settings!$J$4:$J$23))) | W21: =IF(V21=0,0,IF(U21=0,V21,WORKDAY(V21,U21-1,Settings!$J$4:$J$23))) | X21: =IF($D21="",0,IF(Settings!$D$17=0,0,MAX(1,ROUND(Settings!$D$17*Settings!$C$5*($D21/Settings!$C$6)^Settings!$E$17*IF(Settings!$C$17="Lara",$E21/$F21,1),0)))) | Y21: =IF(W21=0,0,IF(X21=0,W21,WORKDAY(W21,1+Settings!$C$7,Settings!$J$4:$J$23))) | Z21: =IF(Y21=0,0,IF(X21=0,Y21,WORKDAY(Y21,X21-1,Settings!$J$4:$J$23))) | AA21: =IF($D21="",0,IF(Settings!$D$18=0,0,MAX(1,ROUND(Settings!$D$18*Settings!$C$5*($D21/Settings!$C$6)^Settings!$E$18*IF(Settings!$C$18="Lara",$E21/$F21,1),0)))) | AB21: =IF(Z21=0,0,IF(AA21=0,Z21,WORKDAY(Z21,1+Settings!$C$7,Settings!$J$4:$J$23))) | AC21: =IF(AB21=0,0,IF(AA21=0,AB21,WORKDAY(AB21,AA21-1,Settings!$J$4:$J$23))) | AD21: =IF($D21="",0,IF(Settings!$D$19=0,0,MAX(1,ROUND(Settings!$D$19*Settings!$C$5*($D21/Settings!$C$6)^Settings!$E$19*IF(Settings!$C$19="Lara",$E21/$F21,1),0)))) | AE21: =IF(AC21=0,0,IF(AD21=0,AC21,WORKDAY(AC21,1+Settings!$C$7,Settings!$J$4:$J$23))) | AF21: =IF(AE21=0,0,IF(AD21=0,AE21,WORKDAY(AE21,AD21-1,Settings!$J$4:$J$23))) | AG21: =AF21 | AH21: =IF($D21="",0,(I21*(Settings!$C$12="Lara")+L21*(Settings!$C$13="Lara")+O21*(Settings!$C$14="Lara")+R21*(Settings!$C$15="Lara")+U21*(Settings!$C$16="Lara")+X21*(Settings!$C$17="Lara")+AA21*(Settings!$C$18="Lara")+AD21*(Settings!$C$19="Lara"))*$F21*Settings!$C$4)
A22: 18 | I22: =IF($D22="",0,IF(Settings!$D$12=0,0,MAX(1,ROUND(Settings!$D$12*Settings!$C$5*($D22/Settings!$C$6)^Settings!$E$12*IF(Settings!$C$12="Lara",$E22/$F22,1),0)))) | J22: =IF($G22="",0,WORKDAY($G22-1,1,Settings!$J$4:$J$23)) | K22: =IF(J22=0,0,IF(I22=0,J22,WORKDAY(J22,I22-1,Settings!$J$4:$J$23))) | L22: =IF($D22="",0,IF(Settings!$D$13=0,0,MAX(1,ROUND(Settings!$D$13*Settings!$C$5*($D22/Settings!$C$6)^Settings!$E$13*IF(Settings!$C$13="Lara",$E22/$F22,1),0)))) | M22: =IF(K22=0,0,IF(L22=0,K22,WORKDAY(K22,1+Settings!$C$7,Settings!$J$4:$J$23))) | N22: =IF(M22=0,0,IF(L22=0,M22,WORKDAY(M22,L22-1,Settings!$J$4:$J$23))) | O22: =IF($D22="",0,IF(Settings!$D$14=0,0,MAX(1,ROUND(Settings!$D$14*Settings!$C$5*($D22/Settings!$C$6)^Settings!$E$14*IF(Settings!$C$14="Lara",$E22/$F22,1),0)))) | P22: =IF(N22=0,0,IF(O22=0,N22,WORKDAY(N22,1+Settings!$C$7,Settings!$J$4:$J$23))) | Q22: =IF(P22=0,0,IF(O22=0,P22,WORKDAY(P22,O22-1,Settings!$J$4:$J$23))) | R22: =IF($D22="",0,IF(Settings!$D$15=0,0,MAX(1,ROUND(Settings!$D$15*Settings!$C$5*($D22/Settings!$C$6)^Settings!$E$15*IF(Settings!$C$15="Lara",$E22/$F22,1),0)))) | S22: =IF(Q22=0,0,IF(R22=0,Q22,WORKDAY(Q22,1+Settings!$C$7,Settings!$J$4:$J$23))) | T22: =IF(S22=0,0,IF(R22=0,S22,WORKDAY(S22,R22-1,Settings!$J$4:$J$23))) | U22: =IF($D22="",0,IF(Settings!$D$16=0,0,MAX(1,ROUND(Settings!$D$16*Settings!$C$5*($D22/Settings!$C$6)^Settings!$E$16*IF(Settings!$C$16="Lara",$E22/$F22,1),0)))) | V22: =IF(T22=0,0,IF(U22=0,T22,WORKDAY(T22,1+Settings!$C$7,Settings!$J$4:$J$23))) | W22: =IF(V22=0,0,IF(U22=0,V22,WORKDAY(V22,U22-1,Settings!$J$4:$J$23))) | X22: =IF($D22="",0,IF(Settings!$D$17=0,0,MAX(1,ROUND(Settings!$D$17*Settings!$C$5*($D22/Settings!$C$6)^Settings!$E$17*IF(Settings!$C$17="Lara",$E22/$F22,1),0)))) | Y22: =IF(W22=0,0,IF(X22=0,W22,WORKDAY(W22,1+Settings!$C$7,Settings!$J$4:$J$23))) | Z22: =IF(Y22=0,0,IF(X22=0,Y22,WORKDAY(Y22,X22-1,Settings!$J$4:$J$23))) | AA22: =IF($D22="",0,IF(Settings!$D$18=0,0,MAX(1,ROUND(Settings!$D$18*Settings!$C$5*($D22/Settings!$C$6)^Settings!$E$18*IF(Settings!$C$18="Lara",$E22/$F22,1),0)))) | AB22: =IF(Z22=0,0,IF(AA22=0,Z22,WORKDAY(Z22,1+Settings!$C$7,Settings!$J$4:$J$23))) | AC22: =IF(AB22=0,0,IF(AA22=0,AB22,WORKDAY(AB22,AA22-1,Settings!$J$4:$J$23))) | AD22: =IF($D22="",0,IF(Settings!$D$19=0,0,MAX(1,ROUND(Settings!$D$19*Settings!$C$5*($D22/Settings!$C$6)^Settings!$E$19*IF(Settings!$C$19="Lara",$E22/$F22,1),0)))) | AE22: =IF(AC22=0,0,IF(AD22=0,AC22,WORKDAY(AC22,1+Settings!$C$7,Settings!$J$4:$J$23))) | AF22: =IF(AE22=0,0,IF(AD22=0,AE22,WORKDAY(AE22,AD22-1,Settings!$J$4:$J$23))) | AG22: =AF22 | AH22: =IF($D22="",0,(I22*(Settings!$C$12="Lara")+L22*(Settings!$C$13="Lara")+O22*(Settings!$C$14="Lara")+R22*(Settings!$C$15="Lara")+U22*(Settings!$C$16="Lara")+X22*(Settings!$C$17="Lara")+AA22*(Settings!$C$18="Lara")+AD22*(Settings!$C$19="Lara"))*$F22*Settings!$C$4)
... A34: 30 | I34: =IF($D34="",0,IF(Settings!$D$12=0,0,MAX(1,ROUND(Settings!$D$12*Settings!$C$5*($D34/Settings!$C$6)^Settings!$E$12*IF(Settings!$C$12="Lara",$E34/$F34,1),0)))) | J34: =IF($G34="",0,WORKDAY($G34-1,1,Settings!$J$4:$J$23)) | K34: =IF(J34=0,0,IF(I34=0,J34,WORKDAY(J34,I34-1,Settings!$J$4:$J$23))) | L34: =IF($D34="",0,IF(Settings!$D$13=0,0,MAX(1,ROUND(Settings!$D$13*Settings!$C$5*($D34/Settings!$C$6)^Settings!$E$13*IF(Settings!$C$13="Lara",$E34/$F34,1),0)))) | M34: =IF(K34=0,0,IF(L34=0,K34,WORKDAY(K34,1+Settings!$C$7,Settings!$J$4:$J$23))) | N34: =IF(M34=0,0,IF(L34=0,M34,WORKDAY(M34,L34-1,Settings!$J$4:$J$23))) | O34: =IF($D34="",0,IF(Settings!$D$14=0,0,MAX(1,ROUND(Settings!$D$14*Settings!$C$5*($D34/Settings!$C$6)^Settings!$E$14*IF(Settings!$C$14="Lara",$E34/$F34,1),0)))) | P34: =IF(N34=0,0,IF(O34=0,N34,WORKDAY(N34,1+Settings!$C$7,Settings!$J$4:$J$23))) | Q34: =IF(P34=0,0,IF(O34=0,P34,WORKDAY(P34,O34-1,Settings!$J$4:$J$23))) | R34: =IF($D34="",0,IF(Settings!$D$15=0,0,MAX(1,ROUND(Settings!$D$15*Settings!$C$5*($D34/Settings!$C$6)^Settings!$E$15*IF(Settings!$C$15="Lara",$E34/$F34,1),0)))) | S34: =IF(Q34=0,0,IF(R34=0,Q34,WORKDAY(Q34,1+Settings!$C$7,Settings!$J$4:$J$23))) | T34: =IF(S34=0,0,IF(R34=0,S34,WORKDAY(S34,R34-1,Settings!$J$4:$J$23))) | U34: =IF($D34="",0,IF(Settings!$D$16=0,0,MAX(1,ROUND(Settings!$D$16*Settings!$C$5*($D34/Settings!$C$6)^Settings!$E$16*IF(Settings!$C$16="Lara",$E34/$F34,1),0)))) | V34: =IF(T34=0,0,IF(U34=0,T34,WORKDAY(T34,1+Settings!$C$7,Settings!$J$4:$J$23))) | W34: =IF(V34=0,0,IF(U34=0,V34,WORKDAY(V34,U34-1,Settings!$J$4:$J$23))) | X34: =IF($D34="",0,IF(Settings!$D$17=0,0,MAX(1,ROUND(Settings!$D$17*Settings!$C$5*($D34/Settings!$C$6)^Settings!$E$17*IF(Settings!$C$17="Lara",$E34/$F34,1),0)))) | Y34: =IF(W34=0,0,IF(X34=0,W34,WORKDAY(W34,1+Settings!$C$7,Settings!$J$4:$J$23))) | Z34: =IF(Y34=0,0,IF(X34=0,Y34,WORKDAY(Y34,X34-1,Settings!$J$4:$J$23))) | AA34: =IF($D34="",0,IF(Settings!$D$18=0,0,MAX(1,ROUND(Settings!$D$18*Settings!$C$5*($D34/Settings!$C$6)^Settings!$E$18*IF(Settings!$C$18="Lara",$E34/$F34,1),0)))) | AB34: =IF(Z34=0,0,IF(AA34=0,Z34,WORKDAY(Z34,1+Settings!$C$7,Settings!$J$4:$J$23))) | AC34: =IF(AB34=0,0,IF(AA34=0,AB34,WORKDAY(AB34,AA34-1,Settings!$J$4:$J$23))) | AD34: =IF($D34="",0,IF(Settings!$D$19=0,0,MAX(1,ROUND(Settings!$D$19*Settings!$C$5*($D34/Settings!$C$6)^Settings!$E$19*IF(Settings!$C$19="Lara",$E34/$F34,1),0)))) | AE34: =IF(AC34=0,0,IF(AD34=0,AC34,WORKDAY(AC34,1+Settings!$C$7,Settings!$J$4:$J$23))) | AF34: =IF(AE34=0,0,IF(AD34=0,AE34,WORKDAY(AE34,AD34-1,Settings!$J$4:$J$23))) | AG34: =AF34 | AH34: =IF($D34="",0,(I34*(Settings!$C$12="Lara")+L34*(Settings!$C$13="Lara")+O34*(Settings!$C$14="Lara")+R34*(Settings!$C$15="Lara")+U34*(Settings!$C$16="Lara")+X34*(Settings!$C$17="Lara")+AA34*(Settings!$C$18="Lara")+AD34*(Settings!$C$19="Lara"))*$F34*Settings!$C$4)
